<?xml version="1.0" encoding="utf-8"?>
<!-- =================================================================================== -->
<!-- |    This document was autogenerated by xacro from dvrk_launch.urdf.xacro         | -->
<!-- |    EDITING THIS FILE BY HAND IS NOT RECOMMENDED                                 | -->
<!-- =================================================================================== -->
<robot name="master">
  <!--xacro:include filename="$(find dvrk_description)/tool_lnd/tool_lnd.urdf.xacro"/-->
  <link name="world"/>
  <joint name="fixed" type="fixed">
    <origin rpy="0 0 0" xyz="0 0 0.167458"/>
    <parent link="world"/>
    <child link="base_link"/>
  </joint>
  <link name="base_link">
    <inertial>
      <origin rpy="0 0 0" xyz="0 -0.163432953037324 0.552457766148795"/>
      <mass value="251.331338880703"/>
      <inertia ixx="116.092010218379" ixy="0" ixz="0" iyy="116.786187825287" iyz="-2.79449977491914" izz="20.7204503058012"/>
    </inertial>
    <visual>
      <origin rpy="0 0 0" xyz="0 0 0"/>
      <geometry>
        <mesh filename="package://dvrk_description/suj/meshes/base_link.STL"/>
      </geometry>
      <material name="">
        <color rgba="0.647058823529412 0.619607843137255 0.588235294117647 1"/>
      </material>
    </visual>
    <collision>
      <origin rpy="0 0 0" xyz="0 0 0"/>
      <geometry>
        <mesh filename="package://dvrk_description/suj/meshes/base_link.STL"/>
      </geometry>
    </collision>
  </link>
  <link name="suj_psm2_L0">
    <inertial>
      <origin rpy="0 0 0" xyz="0.0568399826690053 0 0.148466700879736"/>
      <mass value="8.19045158700103"/>
      <inertia ixx="0.0849399138017183" ixy="0" ixz="-0.00950408519583723" iyy="0.0840388037894648" iyz="0" izz="0.0337578517914833"/>
    </inertial>
    <visual>
      <origin rpy="0 0 0" xyz="0 0 0"/>
      <geometry>
        <mesh filename="package://dvrk_description/suj/meshes/suj_psm2_L0.STL"/>
      </geometry>
      <material name="">
        <color rgba="0.792156862745098 0.819607843137255 0.933333333333333 1"/>
      </material>
    </visual>
    <collision>
      <origin rpy="0 0 0" xyz="0 0 0"/>
      <geometry>
        <mesh filename="package://dvrk_description/suj/meshes/suj_psm2_L0.STL"/>
      </geometry>
    </collision>
  </link>
  <joint name="suj_psm2_J0" type="prismatic">
    <origin rpy="-3.14159265358979 0 3.14159265358979" xyz="0.1912 -0.101599999999999 0.761099999999999"/>
    <parent link="base_link"/>
    <child link="suj_psm2_L0"/>
    <axis xyz="0 0 -1"/>
    <limit effort="50" lower="-0.3798" upper="0.8425" velocity="50"/>
  </joint>
  <link name="suj_psm2_L1">
    <inertial>
      <origin rpy="0 0 0" xyz="0 0.181423473764042 -0.108873680906329"/>
      <mass value="4.285154468433"/>
      <inertia ixx="0.165298975805322" ixy="0" ixz="0" iyy="0.0318879130435778" iyz="-0.0216382058279061" izz="0.151812373014208"/>
    </inertial>
    <visual>
      <origin rpy="0 0 0" xyz="0 0 0"/>
      <geometry>
        <mesh filename="package://dvrk_description/suj/meshes/suj_psm2_L1.STL"/>
      </geometry>
      <material name="">
        <color rgba="0.792156862745098 0.819607843137255 0.933333333333333 1"/>
      </material>
    </visual>
    <collision>
      <origin rpy="0 0 0" xyz="0 0 0"/>
      <geometry>
        <mesh filename="package://dvrk_description/suj/meshes/suj_psm2_L1.STL"/>
      </geometry>
    </collision>
  </link>
  <joint name="suj_psm2_J1" type="continuous">
    <origin rpy="0 0 1.5707963267949" xyz="0 0 0"/>
    <parent link="suj_psm2_L0"/>
    <child link="suj_psm2_L1"/>
    <axis xyz="0 0 -1"/>
  </joint>
  <link name="suj_psm2_L2">
    <inertial>
      <origin rpy="0 0 0" xyz="0.208919873467034 0 0.0907666144838899"/>
      <mass value="3.37391295638727"/>
      <inertia ixx="0.0170495937307872" ixy="0" ixz="0.0010255647636027" iyy="0.12264804166409" iyz="0" izz="0.114779656818464"/>
    </inertial>
    <visual>
      <origin rpy="0 0 0" xyz="0 0 0"/>
      <geometry>
        <mesh filename="package://dvrk_description/suj/meshes/suj_psm2_L2.STL"/>
      </geometry>
      <material name="">
        <color rgba="0.792156862745098 0.819607843137255 0.933333333333333 1"/>
      </material>
    </visual>
    <collision>
      <origin rpy="0 0 0" xyz="0 0 0"/>
      <geometry>
        <mesh filename="package://dvrk_description/suj/meshes/suj_psm2_L2.STL"/>
      </geometry>
    </collision>
  </link>
  <joint name="suj_psm2_J2" type="continuous">
    <origin rpy="3.14159265358979 0 1.5707963267949" xyz="0 0.4318 -0.17125"/>
    <parent link="suj_psm2_L1"/>
    <child link="suj_psm2_L2"/>
    <axis xyz="0 0 1"/>
  </joint>
  <link name="suj_psm2_L3">
    <inertial>
      <origin rpy="0 0 0" xyz="0 0.0671937597670209 -0.0457966340632676"/>
      <mass value="0.955411449199707"/>
      <inertia ixx="0.00502239974642487" ixy="0" ixz="0" iyy="0.00485366592677737" iyz="0.000256157144769027" izz="0.00220603249495337"/>
    </inertial>
    <visual>
      <origin rpy="0 0 0" xyz="0 0 0"/>
      <geometry>
        <mesh filename="package://dvrk_description/suj/meshes/suj_psm2_L3.STL"/>
      </geometry>
      <material name="">
        <color rgba="0.792156862745098 0.819607843137255 0.933333333333333 1"/>
      </material>
    </visual>
    <collision>
      <origin rpy="0 0 0" xyz="0 0 0"/>
      <geometry>
        <mesh filename="package://dvrk_description/suj/meshes/suj_psm2_L3.STL"/>
      </geometry>
    </collision>
  </link>
  <joint name="suj_psm2_J3" type="continuous">
    <origin rpy="-1.5707963267949 0 -1.5707963267949" xyz="0.4318 0 0"/>
    <parent link="suj_psm2_L2"/>
    <child link="suj_psm2_L3"/>
    <axis xyz="0 -1 0"/>
  </joint>
  <link name="suj_psm2_L4">
    <inertial>
      <origin rpy="0 0 0" xyz="0 0.13368960726033 0.106531287729481"/>
      <mass value="3.17073043883153"/>
      <inertia ixx="0.081480486654553" ixy="0" ixz="0" iyy="0.0179293368302569" iyz="-0.0218807182526152" izz="0.0668098507562024"/>
    </inertial>
    <visual>
      <origin rpy="0 0 0" xyz="0 0 0"/>
      <geometry>
        <mesh filename="package://dvrk_description/suj/meshes/suj_psm2_L4.STL"/>
      </geometry>
      <material name="">
        <color rgba="0.792156862745098 0.819607843137255 0.933333333333333 1"/>
      </material>
    </visual>
    <collision>
      <origin rpy="0 0 0" xyz="0 0 0"/>
      <geometry>
        <mesh filename="package://dvrk_description/suj/meshes/suj_psm2_L4.STL"/>
      </geometry>
    </collision>
  </link>
  <joint name="suj_psm2_J4" type="continuous">
    <origin rpy="1.5707963267949 0 3.14159265358979" xyz="0 0.0730499999999998 0.0609999999999997"/>
    <parent link="suj_psm2_L3"/>
    <child link="suj_psm2_L4"/>
    <axis xyz="0 1 0"/>
  </joint>
  <link name="suj_ecm_L0">
    <inertial>
      <origin rpy="0 0 0" xyz="0.0568399826690054 0 0.148466700879736"/>
      <mass value="8.19045158700106"/>
      <inertia ixx="0.0849399138017188" ixy="0" ixz="-0.00950408519583733" iyy="0.0840388037894653" iyz="0" izz="0.0337578517914834"/>
    </inertial>
    <visual>
      <origin rpy="0 0 0" xyz="0 0 0"/>
      <geometry>
        <mesh filename="package://dvrk_description/suj/meshes/suj_ecm_L0.STL"/>
      </geometry>
      <material name="">
        <color rgba="0.792156862745098 0.819607843137255 0.933333333333333 1"/>
      </material>
    </visual>
    <collision>
      <origin rpy="0 0 0" xyz="0 0 0"/>
      <geometry>
        <mesh filename="package://dvrk_description/suj/meshes/suj_ecm_L0.STL"/>
      </geometry>
    </collision>
  </link>
  <joint name="suj_ecm_J0" type="prismatic">
    <origin rpy="3.14159265358979 0 -1.5707963267949" xyz="0 0.0896 0.7611"/>
    <parent link="base_link"/>
    <child link="suj_ecm_L0"/>
    <axis xyz="0 0 -1"/>
    <limit effort="50" lower="-0.3798" upper="0.8425" velocity="50"/>
  </joint>
  <link name="suj_ecm_L1">
    <inertial>
      <origin rpy="0 0 0" xyz="0 -0.181423473764043 0.108873680906329"/>
      <mass value="4.28515446843305"/>
      <inertia ixx="0.165298975805323" ixy="0" ixz="0" iyy="0.0318879130435779" iyz="-0.0216382058279063" izz="0.151812373014209"/>
    </inertial>
    <visual>
      <origin rpy="0 0 0" xyz="0 0 0"/>
      <geometry>
        <mesh filename="package://dvrk_description/suj/meshes/suj_ecm_L1.STL"/>
      </geometry>
      <material name="">
        <color rgba="0.792156862745098 0.819607843137255 0.933333333333333 1"/>
      </material>
    </visual>
    <collision>
      <origin rpy="0 0 0" xyz="0 0 0"/>
      <geometry>
        <mesh filename="package://dvrk_description/suj/meshes/suj_ecm_L1.STL"/>
      </geometry>
    </collision>
  </link>
  <joint name="suj_ecm_J1" type="continuous">
    <origin rpy="3.14159265358979 0 1.5707963267949" xyz="0 0 0"/>
    <parent link="suj_ecm_L0"/>
    <child link="suj_ecm_L1"/>
    <axis xyz="0 0 1"/>
  </joint>
  <link name="suj_ecm_L2">
    <inertial>
      <origin rpy="0 0 0" xyz="0.208919873467034 0 -0.0907666144838897"/>
      <mass value="3.37391295638731"/>
      <inertia ixx="0.0170495937307872" ixy="0" ixz="-0.00102556476360276" iyy="0.122648041664091" iyz="0" izz="0.114779656818464"/>
    </inertial>
    <visual>
      <origin rpy="0 0 0" xyz="0 0 0"/>
      <geometry>
        <mesh filename="package://dvrk_description/suj/meshes/suj_ecm_L2.STL"/>
      </geometry>
      <material name="">
        <color rgba="0.792156862745098 0.819607843137255 0.933333333333333 1"/>
      </material>
    </visual>
    <collision>
      <origin rpy="0 0 0" xyz="0 0 0"/>
      <geometry>
        <mesh filename="package://dvrk_description/suj/meshes/suj_ecm_L2.STL"/>
      </geometry>
    </collision>
  </link>
  <joint name="suj_ecm_J2" type="continuous">
    <origin rpy="3.14159265358979 0 -1.5707963267949" xyz="0 -0.4318 0.17125"/>
    <parent link="suj_ecm_L1"/>
    <child link="suj_ecm_L2"/>
    <axis xyz="0 0 -1"/>
  </joint>
  <link name="suj_ecm_L3">
    <inertial>
      <origin rpy="0 0 0" xyz="0.101750929950522 0.0259124054818911 0"/>
      <mass value="3.45916152951232"/>
      <inertia ixx="0.0229632930111855" ixy="-0.00595610077478554" ixz="0" iyy="0.0229722469896469" iyz="0" izz="0.0422114398260218"/>
    </inertial>
    <visual>
      <origin rpy="0 0 0" xyz="0 0 0"/>
      <geometry>
        <mesh filename="package://dvrk_description/suj/meshes/suj_ecm_L3.STL"/>
      </geometry>
      <material name="">
        <color rgba="0.792156862745098 0.819607843137255 0.933333333333333 1"/>
      </material>
    </visual>
    <collision>
      <origin rpy="0 0 0" xyz="0 0 0"/>
      <geometry>
        <mesh filename="package://dvrk_description/suj/meshes/suj_ecm_L3.STL"/>
      </geometry>
    </collision>
  </link>
  <joint name="suj_ecm_J3" type="continuous">
    <origin rpy="1.5707963267949 0 3.14159265358979" xyz="0.4318 0 0.052"/>
    <parent link="suj_ecm_L2"/>
    <child link="suj_ecm_L3"/>
    <axis xyz="0 -1 0"/>
  </joint>
  <link name="suj_psm1_L0">
    <inertial>
      <origin rpy="0 0 0" xyz="0.056839982669005 0 0.148466700879737"/>
      <mass value="8.19045158700109"/>
      <inertia ixx="0.0849399138017188" ixy="0" ixz="-0.00950408519583709" iyy="0.0840388037894655" iyz="0" izz="0.0337578517914837"/>
    </inertial>
    <visual>
      <origin rpy="0 0 0" xyz="0 0 0"/>
      <geometry>
        <mesh filename="package://dvrk_description/suj/meshes/suj_psm1_L0.STL"/>
      </geometry>
      <material name="">
        <color rgba="0.792156862745098 0.819607843137255 0.933333333333333 1"/>
      </material>
    </visual>
    <collision>
      <origin rpy="0 0 0" xyz="0 0 0"/>
      <geometry>
        <mesh filename="package://dvrk_description/suj/meshes/suj_psm1_L0.STL"/>
      </geometry>
    </collision>
  </link>
  <joint name="suj_psm1_J0" type="prismatic">
    <origin rpy="3.14159265358979 0 0" xyz="-0.191199999999999 -0.1016 0.761099999999999"/>
    <parent link="base_link"/>
    <child link="suj_psm1_L0"/>
    <axis xyz="0 0 -1"/>
    <limit effort="50" lower="-0.3798" upper="0.8425" velocity="50"/>
  </joint>
  <link name="suj_psm1_L1">
    <inertial>
      <origin rpy="0 0 0" xyz="0 0.181423473764042 -0.108873680906329"/>
      <mass value="4.28515446843304"/>
      <inertia ixx="0.165298975805321" ixy="0" ixz="0" iyy="0.0318879130435778" iyz="-0.0216382058279061" izz="0.151812373014208"/>
    </inertial>
    <visual>
      <origin rpy="0 0 0" xyz="0 0 0"/>
      <geometry>
        <mesh filename="package://dvrk_description/suj/meshes/suj_psm1_L1.STL"/>
      </geometry>
      <material name="">
        <color rgba="0.792156862745098 0.819607843137255 0.933333333333333 1"/>
      </material>
    </visual>
    <collision>
      <origin rpy="0 0 0" xyz="0 0 0"/>
      <geometry>
        <mesh filename="package://dvrk_description/suj/meshes/suj_psm1_L1.STL"/>
      </geometry>
    </collision>
  </link>
  <joint name="suj_psm1_J1" type="continuous">
    <origin rpy="0 0 1.5707963267949" xyz="0 0 0"/>
    <parent link="suj_psm1_L0"/>
    <child link="suj_psm1_L1"/>
    <axis xyz="0 0 -1"/>
  </joint>
  <link name="suj_psm1_L2">
    <inertial>
      <origin rpy="0 0 0" xyz="0.208919873467034 0 0.0907666144838897"/>
      <mass value="3.37391295638733"/>
      <inertia ixx="0.0170495937307872" ixy="0" ixz="0.00102556476360271" iyy="0.122648041664091" iyz="0" izz="0.114779656818464"/>
    </inertial>
    <visual>
      <origin rpy="0 0 0" xyz="0 0 0"/>
      <geometry>
        <mesh filename="package://dvrk_description/suj/meshes/suj_psm1_L2.STL"/>
      </geometry>
      <material name="">
        <color rgba="0.792156862745098 0.819607843137255 0.933333333333333 1"/>
      </material>
    </visual>
    <collision>
      <origin rpy="0 0 0" xyz="0 0 0"/>
      <geometry>
        <mesh filename="package://dvrk_description/suj/meshes/suj_psm1_L2.STL"/>
      </geometry>
    </collision>
  </link>
  <joint name="suj_psm1_J2" type="continuous">
    <origin rpy="3.14159265358979 0 1.5707963267949" xyz="0 0.4318 -0.171250000000001"/>
    <parent link="suj_psm1_L1"/>
    <child link="suj_psm1_L2"/>
    <axis xyz="0 0 1"/>
  </joint>
  <link name="suj_psm1_L3">
    <inertial>
      <origin rpy="0 0 0" xyz="0 -0.0671937597670209 0.0457966340632671"/>
      <mass value="0.955411449199707"/>
      <inertia ixx="0.00502239974642493" ixy="0" ixz="0" iyy="0.0048536659267774" iyz="0.000256157144769039" izz="0.00220603249495337"/>
    </inertial>
    <visual>
      <origin rpy="0 0 0" xyz="0 0 0"/>
      <geometry>
        <mesh filename="package://dvrk_description/suj/meshes/suj_psm1_L3.STL"/>
      </geometry>
      <material name="">
        <color rgba="0.792156862745098 0.819607843137255 0.933333333333333 1"/>
      </material>
    </visual>
    <collision>
      <origin rpy="0 0 0" xyz="0 0 0"/>
      <geometry>
        <mesh filename="package://dvrk_description/suj/meshes/suj_psm1_L3.STL"/>
      </geometry>
    </collision>
  </link>
  <joint name="suj_psm1_J3" type="continuous">
    <origin rpy="1.5707963267949 0 -1.5707963267949" xyz="0.4318 0 0"/>
    <parent link="suj_psm1_L2"/>
    <child link="suj_psm1_L3"/>
    <axis xyz="0 1 0"/>
  </joint>
  <link name="suj_psm1_L4">
    <inertial>
      <origin rpy="0 0 0" xyz="0 0.13368960726033 0.106531287729481"/>
      <mass value="3.17073043883155"/>
      <inertia ixx="0.0814804866545533" ixy="0" ixz="0" iyy="0.0179293368302569" iyz="-0.0218807182526152" izz="0.0668098507562027"/>
    </inertial>
    <visual>
      <origin rpy="0 0 0" xyz="0 0 0"/>
      <geometry>
        <mesh filename="package://dvrk_description/suj/meshes/suj_psm1_L4.STL"/>
      </geometry>
      <material name="">
        <color rgba="0.792156862745098 0.819607843137255 0.933333333333333 1"/>
      </material>
    </visual>
    <collision>
      <origin rpy="0 0 0" xyz="0 0 0"/>
      <geometry>
        <mesh filename="package://dvrk_description/suj/meshes/suj_psm1_L4.STL"/>
      </geometry>
    </collision>
  </link>
  <joint name="suj_psm1_J4" type="continuous">
    <origin rpy="-1.5707963267949 0 3.14159265358979" xyz="0 -0.0730499999999998 -0.0609999999999999"/>
    <parent link="suj_psm1_L3"/>
    <child link="suj_psm1_L4"/>
    <axis xyz="0 1 0"/>
  </joint>
  <link name="suj_psm3_L0">
    <inertial>
      <origin rpy="0 0 0" xyz="0.0602109648274594 0 0.113199880625867"/>
      <mass value="6.04817279598793"/>
      <inertia ixx="0.042751844253079" ixy="0" ixz="-0.00566678005551946" iyy="0.0405000183180794" iyz="0" izz="0.023227300149106"/>
    </inertial>
    <visual>
      <origin rpy="0 0 0" xyz="0 0 0"/>
      <geometry>
        <mesh filename="package://dvrk_description/suj/meshes/suj_psm3_L0.STL"/>
      </geometry>
      <material name="">
        <color rgba="0.792156862745098 0.819607843137255 0.933333333333333 1"/>
      </material>
    </visual>
    <collision>
      <origin rpy="0 0 0" xyz="0 0 0"/>
      <geometry>
        <mesh filename="package://dvrk_description/suj/meshes/suj_psm3_L0.STL"/>
      </geometry>
    </collision>
  </link>
  <joint name="suj_psm3_J0" type="prismatic">
    <origin rpy="3.14159265358979 0 -1.5707963267949" xyz="0 0.0895999999999999 0.3813"/>
    <parent link="base_link"/>
    <child link="suj_psm3_L0"/>
    <axis xyz="0 0 -1"/>
    <limit effort="50" lower="0" upper="1.2223" velocity="50"/>
  </joint>
  <link name="suj_psm3_L1">
    <inertial>
      <origin rpy="0 0 0" xyz="0 -0.269226910798469 0.0974465195036079"/>
      <mass value="9.2143433650029"/>
      <inertia ixx="0.512543337774863" ixy="0" ixz="0" iyy="0.046675533244729" iyz="-0.022324667193201" izz="0.500775909008121"/>
    </inertial>
    <visual>
      <origin rpy="0 0 0" xyz="0 0 0"/>
      <geometry>
        <mesh filename="package://dvrk_description/suj/meshes/suj_psm3_L1.STL"/>
      </geometry>
      <material name="">
        <color rgba="0.792156862745098 0.819607843137255 0.933333333333333 1"/>
      </material>
    </visual>
    <collision>
      <origin rpy="0 0 0" xyz="0 0 0"/>
      <geometry>
        <mesh filename="package://dvrk_description/suj/meshes/suj_psm3_L1.STL"/>
      </geometry>
    </collision>
  </link>
  <joint name="suj_psm3_J1" type="continuous">
    <origin rpy="3.14159265358979 0 1.5707963267949" xyz="0 0 0"/>
    <parent link="suj_psm3_L0"/>
    <child link="suj_psm3_L1"/>
    <axis xyz="0 0 1"/>
  </joint>
  <link name="suj_psm3_L2">
    <inertial>
      <origin rpy="0 0 0" xyz="0.208919873467035 0 0.0907666144838893"/>
      <mass value="3.37391295638732"/>
      <inertia ixx="0.0170495937307872" ixy="0" ixz="0.00102556476360266" iyy="0.122648041664091" iyz="0" izz="0.114779656818464"/>
    </inertial>
    <visual>
      <origin rpy="0 0 0" xyz="0 0 0"/>
      <geometry>
        <mesh filename="package://dvrk_description/suj/meshes/suj_psm3_L2.STL"/>
      </geometry>
      <material name="">
        <color rgba="0.792156862745098 0.819607843137255 0.933333333333333 1"/>
      </material>
    </visual>
    <collision>
      <origin rpy="0 0 0" xyz="0 0 0"/>
      <geometry>
        <mesh filename="package://dvrk_description/suj/meshes/suj_psm3_L2.STL"/>
      </geometry>
    </collision>
  </link>
  <joint name="suj_psm3_J2" type="continuous">
    <origin rpy="3.14159265358979 0 -1.5707963267949" xyz="0 -0.5842 -0.000249999999999639"/>
    <parent link="suj_psm3_L1"/>
    <child link="suj_psm3_L2"/>
    <axis xyz="0 0 -1"/>
  </joint>
  <link name="suj_psm3_L3">
    <inertial>
      <origin rpy="0 0 0" xyz="0 -0.147369605966979 0.0299587011265839"/>
      <mass value="1.46016558605931"/>
      <inertia ixx="0.0128891233532759" ixy="0" ixz="0" iyy="0.00658384974944233" iyz="0.00230089243299317" izz="0.00938095830526967"/>
    </inertial>
    <visual>
      <origin rpy="0 0 0" xyz="0 0 0"/>
      <geometry>
        <mesh filename="package://dvrk_description/suj/meshes/suj_psm3_L3.STL"/>
      </geometry>
      <material name="">
        <color rgba="0.792156862745098 0.819607843137255 0.933333333333333 1"/>
      </material>
    </visual>
    <collision>
      <origin rpy="0 0 0" xyz="0 0 0"/>
      <geometry>
        <mesh filename="package://dvrk_description/suj/meshes/suj_psm3_L3.STL"/>
      </geometry>
    </collision>
  </link>
  <joint name="suj_psm3_J3" type="continuous">
    <origin rpy="1.5707963267949 0 -1.5707963267949" xyz="0.431800000000001 0 0"/>
    <parent link="suj_psm3_L2"/>
    <child link="suj_psm3_L3"/>
    <axis xyz="0 -1 0"/>
  </joint>
  <link name="suj_psm3_L4">
    <inertial>
      <origin rpy="0 0 0" xyz="0 0.133689607260329 0.106531287729481"/>
      <mass value="3.17073043883155"/>
      <inertia ixx="0.0814804866545532" ixy="0" ixz="0" iyy="0.0179293368302569" iyz="-0.0218807182526152" izz="0.0668098507562025"/>
    </inertial>
    <visual>
      <origin rpy="0 0 0" xyz="0 0 0"/>
      <geometry>
        <mesh filename="package://dvrk_description/suj/meshes/suj_psm3_L4.STL"/>
      </geometry>
      <material name="">
        <color rgba="0.792156862745098 0.819607843137255 0.933333333333333 1"/>
      </material>
    </visual>
    <collision>
      <origin rpy="0 0 0" xyz="0 0 0"/>
      <geometry>
        <mesh filename="package://dvrk_description/suj/meshes/suj_psm3_L4.STL"/>
      </geometry>
    </collision>
  </link>
  <joint name="suj_psm3_J4" type="continuous">
    <origin rpy="-1.5707963267949 0 0" xyz="0 -0.199949999999999 -0.061"/>
    <parent link="suj_psm3_L3"/>
    <child link="suj_psm3_L4"/>
    <axis xyz="0 1 0"/>
  </joint>
  <!-- //////////////////////////////////////////////////////////////////////////// -->
  <!-- Joint 0: Fixed to Setup Joint-->
  <joint name="fixed_joint" type="fixed">
    <parent link="suj_ecm_L3"/>
    <child link="ecm_base_link"/>
    <origin rpy="-1.5708 0 2.404602" xyz="0.103 0.173 0"/>
  </joint>
  <link name="ecm_base_link">
    <inertial>
      <origin rpy="0 0 0" xyz="-0.0048227 0 0.068959"/>
      <mass value="2.6363"/>
      <inertia ixx="0" ixy="0" ixz="0" iyy="0" iyz="0" izz="0"/>
    </inertial>
    <visual>
      <origin rpy="0 0 0" xyz="0 0 0"/>
      <geometry>
        <mesh filename="package://dvrk_description/ecm//meshes/base_link.STL"/>
      </geometry>
      <material name="">
        <color rgba="0.64706 0.61961 0.58824 1"/>
      </material>
    </visual>
    <collision>
      <origin rpy="0 0 0" xyz="0 0 0"/>
      <geometry>
        <mesh filename="package://dvrk_description/ecm//meshes/base_link.STL"/>
      </geometry>
    </collision>
  </link>
  <link name="ecm_yaw_link">
    <inertial>
      <origin rpy="0 0 0" xyz="0 -0.029045 0.10669"/>
      <mass value="6.4168"/>
      <inertia ixx="0.00086598" ixy="0" ixz="0" iyy="0.0016561" iyz="-0.00015825" izz="0.00085001"/>
    </inertial>
    <visual>
      <origin rpy="0 0 0" xyz="0 0 0"/>
      <geometry>
        <mesh filename="package://dvrk_description/ecm//meshes/yaw_link.STL"/>
      </geometry>
      <material name="">
        <color rgba="0.64706 0.61961 0.58824 1"/>
      </material>
    </visual>
    <collision>
      <origin rpy="0 0 0" xyz="0 0 0"/>
      <geometry>
        <mesh filename="package://dvrk_description/ecm//meshes/yaw_link.STL"/>
      </geometry>
    </collision>
  </link>
  <joint name="ecm_yaw_joint" type="revolute">
    <origin rpy="1.57079632679615 0 1.5707963267949" xyz="0.0731999999999783 0 0.101460000000185"/>
    <parent link="ecm_base_link"/>
    <child link="ecm_yaw_link"/>
    <axis xyz="0 0 1"/>
    <limit effort="1000" lower="-1.595183" upper="1.581733" velocity="10"/>
  </joint>
  <link name="ecm_pitch_front_link">
    <inertial>
      <origin rpy="0 0 0" xyz="-0.030619 -0.13578 0"/>
      <mass value="1.6069"/>
      <inertia ixx="0" ixy="0" ixz="0" iyy="0" iyz="0" izz="0"/>
    </inertial>
    <visual>
      <origin rpy="0 0 0" xyz="0 0 0"/>
      <geometry>
        <mesh filename="package://dvrk_description/ecm//meshes/pitch_front_link.STL"/>
      </geometry>
      <material name="">
        <color rgba="0.64706 0.61961 0.58824 1"/>
      </material>
    </visual>
    <collision>
      <origin rpy="0 0 0" xyz="0 0 0"/>
      <geometry>
        <mesh filename="package://dvrk_description/ecm//meshes/pitch_front_link.STL"/>
      </geometry>
    </collision>
  </link>
  <joint name="ecm_pitch_front_joint" type="revolute">
    <origin rpy="3.14 -1.5707963267949 0" xyz="0 0 0.199000000000014"/>
    <parent link="ecm_yaw_link"/>
    <child link="ecm_pitch_front_link"/>
    <axis xyz="0 0 1"/>
    <limit effort="1000" lower="-0.783710" upper="1.157657" velocity="10"/>
  </joint>
  <link name="ecm_pitch_bottom_link">
    <inertial>
      <origin rpy="0 0 0" xyz="0.14594 -0.026715 -0.00016488"/>
      <mass value="0.35928"/>
      <inertia ixx="0.00023901" ixy="0.00022767" ixz="0" iyy="0.0030096" iyz="0" izz="0.0029617"/>
    </inertial>
    <visual>
      <origin rpy="0 0 0" xyz="0 0 0"/>
      <geometry>
        <mesh filename="package://dvrk_description/ecm//meshes/pitch_bottom_link.STL"/>
      </geometry>
      <material name="">
        <color rgba="0.25098 0.25098 0.25098 1"/>
      </material>
    </visual>
    <collision>
      <origin rpy="0 0 0" xyz="0 0 0"/>
      <geometry>
        <mesh filename="package://dvrk_description/ecm//meshes/pitch_bottom_link.STL"/>
      </geometry>
    </collision>
  </link>
  <joint name="ecm_pitch_bottom_joint" type="revolute">
    <origin rpy="0 0 0" xyz="-0.103000865501078 -0.286804989831434 0"/>
    <parent link="ecm_pitch_front_link"/>
    <child link="ecm_pitch_bottom_link"/>
    <axis xyz="0 0 1"/>
    <limit effort="1000" lower="-1.157657" upper="0.783710" velocity="10"/>
    <mimic joint="ecm_pitch_front_joint" multiplier="-1"/>
  </joint>
  <link name="ecm_pitch_end_link">
    <inertial>
      <origin rpy="0 0 0" xyz="0.018122 -0.027143 0.00078916"/>
      <mass value="2.0321"/>
      <inertia ixx="0" ixy="0" ixz="0" iyy="0" iyz="0" izz="0"/>
    </inertial>
    <visual>
      <origin rpy="0 0 0" xyz="0 0 0"/>
      <geometry>
        <mesh filename="package://dvrk_description/ecm//meshes/pitch_end_link.STL"/>
      </geometry>
      <material name="">
        <color rgba="0.89804 0.91765 0.92941 1"/>
      </material>
    </visual>
    <collision>
      <origin rpy="0 0 0" xyz="0 0 0"/>
      <geometry>
        <mesh filename="package://dvrk_description/ecm//meshes/pitch_end_link.STL"/>
      </geometry>
    </collision>
  </link>
  <joint name="ecm_pitch_end_joint" type="revolute">
    <origin rpy="0 0 0" xyz="0.340400072983362 -0.000135620545844151 0"/>
    <parent link="ecm_pitch_bottom_link"/>
    <child link="ecm_pitch_end_link"/>
    <axis xyz="0 0 1"/>
    <limit effort="1000" lower="-0.783710" upper="1.157657" velocity="10"/>
    <mimic joint="ecm_pitch_front_joint" multiplier="1"/>
  </joint>
  <link name="ecm_main_insertion_link">
    <inertial>
      <origin rpy="0 0 0" xyz="0.0086165 -0.00079249 -0.047928"/>
      <mass value="0.23108"/>
      <inertia ixx="0" ixy="0" ixz="0" iyy="0" iyz="0" izz="0"/>
    </inertial>
    <visual>
      <origin rpy="0 0 0" xyz="0 0 0"/>
      <geometry>
        <mesh filename="package://dvrk_description/ecm//meshes/main_insertion_link.STL"/>
      </geometry>
      <material name="">
        <color rgba="0.25098 0.25098 0.25098 1"/>
      </material>
    </visual>
    <collision>
      <origin rpy="0 0 0" xyz="0 0 0"/>
      <geometry>
        <mesh filename="package://dvrk_description/ecm//meshes/main_insertion_link.STL"/>
      </geometry>
    </collision>
  </link>
  <joint name="ecm_main_insertion_joint" type="prismatic">
    <origin rpy="-1.5708 0 0" xyz="0.042 -0.086143 0"/>
    <parent link="ecm_pitch_end_link"/>
    <child link="ecm_main_insertion_link"/>
    <axis xyz="0 0 1"/>
    <limit effort="50" lower="0" upper="0.254193" velocity="100"/>
  </joint>
  <link name="ecm_tool_link">
    <inertial>
      <origin rpy="0 0 0" xyz="0 -0.0007925 -0.10732"/>
      <mass value="1.9074"/>
      <inertia ixx="0" ixy="0" ixz="0" iyy="0" iyz="0" izz="0"/>
    </inertial>
    <visual>
      <origin rpy="0 0 0" xyz="0 0 0"/>
      <geometry>
        <mesh filename="package://dvrk_description/ecm//meshes/tool_link.STL"/>
      </geometry>
      <material name="">
        <color rgba="0.75294 0.75294 0.75294 1"/>
      </material>
    </visual>
    <collision>
      <origin rpy="0 0 0" xyz="0 0 0"/>
      <geometry>
        <mesh filename="package://dvrk_description/ecm//meshes/tool_link.STL"/>
      </geometry>
    </collision>
  </link>
  <joint name="ecm_tool_joint" type="revolute">
    <origin rpy="0 0 0" xyz="0.0609999999999996 0 0"/>
    <parent link="ecm_main_insertion_link"/>
    <child link="ecm_tool_link"/>
    <axis xyz="0 0 -1"/>
    <limit effort="1000" lower="-1.552676" upper="1.566741" velocity="10"/>
  </joint>
  <link name="ecm_pitch_top_link">
    <inertial>
      <origin rpy="0 0 0" xyz="0.1702 0 0.0007925"/>
      <mass value="0.43851"/>
      <inertia ixx="0" ixy="0" ixz="0" iyy="0" iyz="0" izz="0"/>
    </inertial>
    <visual>
      <origin rpy="0 0 0" xyz="0 0 0"/>
      <geometry>
        <mesh filename="package://dvrk_description/ecm//meshes/pitch_top_link.STL"/>
      </geometry>
      <material name="">
        <color rgba="0.64706 0.51765 0 1"/>
      </material>
    </visual>
    <collision>
      <origin rpy="0 0 0" xyz="0 0 0"/>
      <geometry>
        <mesh filename="package://dvrk_description/ecm//meshes/pitch_top_link.STL"/>
      </geometry>
    </collision>
  </link>
  <joint name="ecm_pitch_top_joint" type="revolute">
    <origin rpy="0 0 0" xyz="-0.10847228839493 -0.324257434492051 0"/>
    <parent link="ecm_pitch_front_link"/>
    <child link="ecm_pitch_top_link"/>
    <axis xyz="0 0 1"/>
    <limit effort="1000" lower="-1.157657" upper="0.783710" velocity="10"/>
    <mimic joint="ecm_pitch_front_joint" multiplier="-1"/>
  </joint>
  <link name="ecm_pitch_back_link">
    <inertial>
      <origin rpy="0 0 0" xyz="-0.032853 -0.14997 -0.0080613"/>
      <mass value="0.4214"/>
      <inertia ixx="0" ixy="0" ixz="0" iyy="0" iyz="0" izz="0"/>
    </inertial>
    <visual>
      <origin rpy="0 0 0" xyz="0 0 0"/>
      <geometry>
        <mesh filename="package://dvrk_description/ecm//meshes/pitch_back_link.STL"/>
      </geometry>
      <material name="">
        <color rgba="0.64706 0.51765 0 1"/>
      </material>
    </visual>
    <collision>
      <origin rpy="0 0 0" xyz="0 0 0"/>
      <geometry>
        <mesh filename="package://dvrk_description/ecm//meshes/pitch_back_link.STL"/>
      </geometry>
    </collision>
  </link>
  <joint name="ecm_pitch_back_joint" type="revolute">
    <origin rpy="3.14 -1.5707963267949 0" xyz="0 -0.00979999999999302 0.162430000000002"/>
    <parent link="ecm_yaw_link"/>
    <child link="ecm_pitch_back_link"/>
    <axis xyz="0 0 1"/>
    <limit effort="1000" lower="-0.783710" upper="1.157657" velocity="10"/>
    <mimic joint="ecm_pitch_front_joint" multiplier="1"/>
  </joint>
  <link name="ecm_remote_center_link">
    <inertial>
      <origin rpy="0 0 0" xyz="0 0 0"/>
      <mass value="0.004482"/>
      <inertia ixx="0" ixy="0" ixz="0" iyy="0" iyz="0" izz="0"/>
    </inertial>
    <visual>
      <origin rpy="0 0 0" xyz="0 0 0"/>
      <geometry>
        <mesh filename="package://dvrk_description/ecm//meshes/remote_center_link.STL"/>
      </geometry>
      <material name="">
        <color rgba="1 1 1 1"/>
      </material>
    </visual>
    <collision>
      <origin rpy="0 0 0" xyz="0 0 0"/>
      <geometry>
        <mesh filename="package://dvrk_description/ecm//meshes/remote_center_link.STL"/>
      </geometry>
    </collision>
  </link>
  <joint name="ecm_remote_center_joint" type="fixed">
    <origin rpy="0 0 -1.5707963267949" xyz="0.612599207482277 0 0.10159534323531"/>
    <parent link="ecm_base_link"/>
    <child link="ecm_remote_center_link"/>
    <axis xyz="0 0 0"/>
  </joint>
  <link name="ecm_end_link"/>
  <joint name="ecm_end_joint" type="fixed">
    <origin rpy="0 0 0" xyz="0 0 0.37364"/>
    <parent link="ecm_tool_link"/>
    <child link="ecm_end_link"/>
    <axis xyz="0 0 0"/>
  </joint>
  <joint name="psm1_rev_joint" type="revolute">
    <parent link="suj_psm1_L4"/>
    <child link="psm1_base_link"/>
    <origin rpy="0 3.14159 0" xyz="0 0.3479 -0.0495"/>
    <axis xyz="0 0 1"/>
    <limit effort="1000" lower="-3.14159" upper="3.14159" velocity="10"/>
  </joint>
  <link name="psm1_base_link">
    <inertial>
      <origin rpy="0 0 0" xyz="0 -0.17016 -0.085607"/>
      <mass value="2.0161"/>
      <inertia ixx="0" ixy="0" ixz="0" iyy="0" iyz="0" izz="0"/>
    </inertial>
    <visual>
      <origin rpy="0 0 0" xyz="0 0 0"/>
      <geometry>
        <mesh filename="package://dvrk_description/psm/meshes/base_link.STL"/>
      </geometry>
      <material name="">
        <color rgba="0.89804 0.91765 0.92941 1"/>
      </material>
    </visual>
    <collision>
      <origin rpy="0 0 0" xyz="0 0 0"/>
      <geometry>
        <mesh filename="package://dvrk_description/psm/meshes/base_link.STL"/>
      </geometry>
    </collision>
  </link>
  <link name="psm1_yaw_link">
    <inertial>
      <origin rpy="0 0 0" xyz="-0.038769 0 0.041596"/>
      <mass value="1.4705"/>
      <inertia ixx="0" ixy="0" ixz="0" iyy="0" iyz="0" izz="0"/>
    </inertial>
    <visual>
      <origin rpy="0 0 0" xyz="0 0 0"/>
      <geometry>
        <mesh filename="package://dvrk_description/psm/meshes/yaw_link.STL"/>
      </geometry>
      <material name="">
        <color rgba="0.89804 0.91765 0.92941 1"/>
      </material>
    </visual>
    <collision>
      <origin rpy="0 0 0" xyz="0 0 0"/>
      <geometry>
        <mesh filename="package://dvrk_description/psm/meshes/yaw_link.STL"/>
      </geometry>
    </collision>
  </link>
  <joint name="psm1_yaw_joint" type="revolute">
    <origin rpy="1.5708 -1.5708 0" xyz="0 0 0"/>
    <parent link="psm1_base_link"/>
    <child link="psm1_yaw_link"/>
    <axis xyz="0 0 1"/>
    <limit effort="1000" lower="-1.605" upper="1.5994" velocity="10"/>
  </joint>
  <link name="psm1_pitch_back_link">
    <inertial>
      <origin rpy="0 0 0" xyz="-0.011651 -0.036241 0"/>
      <mass value="0.98494"/>
      <inertia ixx="0" ixy="0" ixz="0" iyy="0" iyz="0" izz="0"/>
    </inertial>
    <visual>
      <origin rpy="0 0 0" xyz="0 0 0"/>
      <geometry>
        <mesh filename="package://dvrk_description/psm/meshes/pitch_back_link.STL"/>
      </geometry>
      <material name="">
        <color rgba="0.89804 0.91765 0.92941 1"/>
      </material>
    </visual>
    <collision>
      <origin rpy="0 0 0" xyz="0 0 0"/>
      <geometry>
        <mesh filename="package://dvrk_description/psm/meshes/pitch_back_link.STL"/>
      </geometry>
    </collision>
  </link>
  <joint name="psm1_pitch_back_joint" type="revolute">
    <origin rpy="-1.5708 -0.29073 0" xyz="0 0 0.0296"/>
    <parent link="psm1_yaw_link"/>
    <child link="psm1_pitch_back_link"/>
    <axis xyz="0 0 1"/>
    <limit effort="1000" lower="-0.93556" upper="0.94249" velocity="10"/>
  </joint>
  <link name="psm1_pitch_bottom_link">
    <inertial>
      <origin rpy="0 0 0" xyz="0.25683 -0.010348 0"/>
      <mass value="0.44569"/>
      <inertia ixx="0" ixy="0" ixz="0" iyy="0" iyz="0" izz="0"/>
    </inertial>
    <visual>
      <origin rpy="0 0 0" xyz="0 0 0"/>
      <geometry>
        <mesh filename="package://dvrk_description/psm/meshes/pitch_bottom_link.STL"/>
      </geometry>
      <material name="">
        <color rgba="0.89804 0.91765 0.92941 1"/>
      </material>
    </visual>
    <collision>
      <origin rpy="0 0 0" xyz="0 0 0"/>
      <geometry>
        <mesh filename="package://dvrk_description/psm/meshes/pitch_bottom_link.STL"/>
      </geometry>
    </collision>
  </link>
  <joint name="psm1_pitch_bottom_joint" type="revolute">
    <origin rpy="0 0 1.8615" xyz="0.15 0 0"/>
    <parent link="psm1_pitch_back_link"/>
    <child link="psm1_pitch_bottom_link"/>
    <axis xyz="0 0 1"/>
    <limit effort="1000" lower="-0.94249" upper="0.93556" velocity="10"/>
    <mimic joint="psm1_pitch_back_joint" multiplier="-1"/>
  </joint>
  <link name="psm1_pitch_end_link">
    <inertial>
      <origin rpy="0 0 0" xyz="-0.0019293 -0.13613 0"/>
      <mass value="2.091"/>
      <inertia ixx="0" ixy="0" ixz="0" iyy="0" iyz="0" izz="0"/>
    </inertial>
    <visual>
      <origin rpy="0 0 0" xyz="0 0 0"/>
      <geometry>
        <mesh filename="package://dvrk_description/psm/meshes/pitch_end_link.STL"/>
      </geometry>
      <material name="">
        <color rgba="0.89804 0.91765 0.92941 1"/>
      </material>
    </visual>
    <collision>
      <origin rpy="0 0 0" xyz="0 0 0"/>
      <geometry>
        <mesh filename="package://dvrk_description/psm/meshes/pitch_end_link.STL"/>
      </geometry>
    </collision>
  </link>
  <joint name="psm1_pitch_end_joint" type="revolute">
    <origin rpy="0 0 0" xyz="0.516 0 0"/>
    <parent link="psm1_pitch_bottom_link"/>
    <child link="psm1_pitch_end_link"/>
    <axis xyz="0 0 1"/>
    <limit effort="1000" lower="-0.93556" upper="0.94249" velocity="10"/>
    <mimic joint="psm1_pitch_back_joint" multiplier="1"/>
  </joint>
  <link name="psm1_main_insertion_link">
    <inertial>
      <origin rpy="0 0 0" xyz="0.0040563 -0.00010934 0.0098616"/>
      <mass value="0.22491"/>
      <inertia ixx="0" ixy="0" ixz="0" iyy="0" iyz="0" izz="0"/>
    </inertial>
    <visual>
      <origin rpy="0 0 1.5708" xyz="0 0 0"/>
      <geometry>
        <mesh filename="package://dvrk_description/psm/meshes/main_insertion_link.STL"/>
      </geometry>
      <material name="">
        <color rgba="1 0.55686 0.058824 0.4"/>
      </material>
    </visual>
    <collision>
      <origin rpy="0 0 0" xyz="0 0 0"/>
      <geometry>
        <mesh filename="package://dvrk_description/psm/meshes/main_insertion_link.STL"/>
      </geometry>
    </collision>
  </link>
  <joint name="psm1_main_insertion_joint" type="prismatic">
    <origin rpy="1.5708 1.5708 3.1416" xyz="0.043 -0.28809 0"/>
    <parent link="psm1_pitch_end_link"/>
    <child link="psm1_main_insertion_link"/>
    <axis xyz="0 0 1"/>
    <limit effort="1000" lower="0" upper="0.24" velocity="1"/>
  </joint>
  <link name="psm1_tool_roll_link">
    <inertial>
      <origin rpy="0 0 0" xyz="0 0 -0.0058234"/>
      <mass value="0.00033225"/>
      <inertia ixx="0" ixy="0" ixz="0" iyy="0" iyz="0" izz="0"/>
    </inertial>
    <visual>
      <origin rpy="0 0 0" xyz="0 0 0"/>
      <geometry>
        <mesh filename="package://dvrk_description/psm/meshes/tool_roll_link.STL"/>
      </geometry>
      <material name="">
        <color rgba="0.79608 0.82353 0.93725 1"/>
      </material>
    </visual>
    <collision>
      <origin rpy="0 0 0" xyz="0 0 0"/>
      <geometry>
        <mesh filename="package://dvrk_description/psm/meshes/tool_roll_link.STL"/>
      </geometry>
    </collision>
  </link>
  <joint name="psm1_tool_roll_joint" type="revolute">
    <origin rpy="0 0 -1.5708" xyz="0 0 0.4162"/>
    <parent link="psm1_main_insertion_link"/>
    <child link="psm1_tool_roll_link"/>
    <axis xyz="0 0 1"/>
    <limit effort="1000" lower="-3.14159" upper="3.14159" velocity="10"/>
  </joint>
  <link name="psm1_tool_pitch_link">
    <inertial>
      <origin rpy="0 0 0" xyz="0.0035763 0 0"/>
      <mass value="0.00025784"/>
      <inertia ixx="0" ixy="0" ixz="0" iyy="0" iyz="0" izz="0"/>
    </inertial>
    <visual>
      <origin rpy="0 0 0" xyz="0 0 0"/>
      <geometry>
        <mesh filename="package://dvrk_description/psm/meshes/tool_pitch_link.STL"/>
      </geometry>
      <material name="">
        <color rgba="0.79608 0.82353 0.93725 1"/>
      </material>
    </visual>
    <collision>
      <origin rpy="0 0 0" xyz="0 0 0"/>
      <geometry>
        <mesh filename="package://dvrk_description/psm/meshes/tool_pitch_link.STL"/>
      </geometry>
    </collision>
  </link>
  <joint name="psm1_tool_pitch_joint" type="revolute">
    <origin rpy="1.5708 -1.5708 3.1416" xyz="0 0 0"/>
    <parent link="psm1_tool_roll_link"/>
    <child link="psm1_tool_pitch_link"/>
    <axis xyz="0 0 1"/>
    <limit effort="1000" lower="-1.5708" upper="1.5708" velocity="10"/>
  </joint>
  <link name="psm1_tool_yaw_link">
    <inertial>
      <origin rpy="0 0 0" xyz="0 0 0"/>
      <mass value="0"/>
      <inertia ixx="0" ixy="0" ixz="0" iyy="0" iyz="0" izz="0"/>
    </inertial>
    <visual>
      <origin rpy="0 0 0" xyz="0 0 0"/>
      <geometry>
        <mesh filename="package://dvrk_description/psm/meshes/tool_yaw_link.STL"/>
      </geometry>
      <material name="">
        <color rgba="0.79608 0.82353 0.93725 1"/>
      </material>
    </visual>
    <collision>
      <origin rpy="0 0 0" xyz="0 0 0"/>
      <geometry>
        <mesh filename="package://dvrk_description/psm/meshes/tool_yaw_link.STL"/>
      </geometry>
    </collision>
  </link>
  <joint name="psm1_tool_yaw_joint" type="revolute">
    <origin rpy="1.5708 -1.5708 3.1416" xyz="0.0091 0 0"/>
    <parent link="psm1_tool_pitch_link"/>
    <child link="psm1_tool_yaw_link"/>
    <axis xyz="0 0 1"/>
    <limit effort="1000" lower="-1.5708" upper="1.5708" velocity="10"/>
  </joint>
  <link name="psm1_tool_gripper1_link">
    <inertial>
      <origin rpy="0 0 0" xyz="0.00019605 0.001435 -0.00088478"/>
      <mass value="0"/>
      <inertia ixx="0" ixy="0" ixz="0" iyy="0" iyz="0" izz="0"/>
    </inertial>
    <visual>
      <origin rpy="0 0 0" xyz="0 0 0"/>
      <geometry>
        <mesh filename="package://dvrk_description/psm/meshes/tool_gripper1_link.STL"/>
      </geometry>
      <material name="">
        <color rgba="0.79608 0.82353 0.93725 1"/>
      </material>
    </visual>
    <collision>
      <origin rpy="0 0 0" xyz="0 0 0"/>
      <geometry>
        <mesh filename="package://dvrk_description/psm/meshes/tool_gripper1_link.STL"/>
      </geometry>
    </collision>
  </link>
  <joint name="psm1_tool_gripper1_joint" type="revolute">
    <origin rpy="0 0 0" xyz="0 0 0"/>
    <parent link="psm1_tool_yaw_link"/>
    <child link="psm1_tool_gripper1_link"/>
    <axis xyz="0 0 1"/>
    <mimic joint="psm1_tool_gripper2_joint" multiplier="-1"/>
    <limit effort="0" lower="0" upper="1" velocity="0"/>
  </joint>
  <link name="psm1_tool_gripper2_link">
    <inertial>
      <origin rpy="0 0 0" xyz="-0.00019605 0.001435 0.00088478"/>
      <mass value="0"/>
      <inertia ixx="0" ixy="0" ixz="0" iyy="0" iyz="0" izz="0"/>
    </inertial>
    <visual>
      <origin rpy="0 0 0" xyz="0 0 0"/>
      <geometry>
        <mesh filename="package://dvrk_description/psm/meshes/tool_gripper2_link.STL"/>
      </geometry>
      <material name="">
        <color rgba="0.79608 0.82353 0.93725 1"/>
      </material>
    </visual>
    <collision>
      <origin rpy="0 0 0" xyz="0 0 0"/>
      <geometry>
        <mesh filename="package://dvrk_description/psm/meshes/tool_gripper2_link.STL"/>
      </geometry>
    </collision>
  </link>
  <joint name="psm1_tool_gripper2_joint" type="revolute">
    <origin rpy="0 0 0" xyz="0 0 0"/>
    <parent link="psm1_tool_yaw_link"/>
    <child link="psm1_tool_gripper2_link"/>
    <axis xyz="0 0 1"/>
    <limit effort="0" lower="0" upper="1" velocity="0"/>
  </joint>
  <link name="psm1_pitch_top_link">
    <inertial>
      <origin rpy="0 0 0" xyz="0.31246 -0.00056566 0"/>
      <mass value="0.17841"/>
      <inertia ixx="0" ixy="0" ixz="0" iyy="0" iyz="0" izz="0"/>
    </inertial>
    <visual>
      <origin rpy="0 0 0" xyz="0 0 0"/>
      <geometry>
        <mesh filename="package://dvrk_description/psm/meshes/pitch_top_link.STL"/>
      </geometry>
      <material name="">
        <color rgba="0.89804 0.91765 0.92941 1"/>
      </material>
    </visual>
    <collision>
      <origin rpy="0 0 0" xyz="0 0 0"/>
      <geometry>
        <mesh filename="package://dvrk_description/psm/meshes/pitch_top_link.STL"/>
      </geometry>
    </collision>
  </link>
  <joint name="psm1_pitch_top_joint" type="revolute">
    <origin rpy="0 0 1.8615" xyz="0.18366 0.014121 0"/>
    <parent link="psm1_pitch_back_link"/>
    <child link="psm1_pitch_top_link"/>
    <axis xyz="0 0 1"/>
    <limit effort="1000" lower="-0.94249" upper="0.93556" velocity="10"/>
    <mimic joint="psm1_pitch_back_joint" multiplier="-1"/>
  </joint>
  <link name="psm1_pitch_front_link">
    <inertial>
      <origin rpy="0 0 0" xyz="0.096269 0 0.047551"/>
      <mass value="0.074425"/>
      <inertia ixx="0" ixy="0" ixz="0" iyy="0" iyz="0" izz="0"/>
    </inertial>
    <visual>
      <origin rpy="0 0 0" xyz="0 0 0"/>
      <geometry>
        <mesh filename="package://dvrk_description/psm/meshes/pitch_front_link.STL"/>
      </geometry>
      <material name="">
        <color rgba="0.89804 0.91765 0.92941 1"/>
      </material>
    </visual>
    <collision>
      <origin rpy="0 0 0" xyz="0 0 0"/>
      <geometry>
        <mesh filename="package://dvrk_description/psm/meshes/pitch_front_link.STL"/>
      </geometry>
    </collision>
  </link>
  <joint name="psm1_pitch_front_joint" type="revolute">
    <origin rpy="-1.5708 -0.29073 0" xyz="0 0 -0.0664"/>
    <parent link="psm1_yaw_link"/>
    <child link="psm1_pitch_front_link"/>
    <axis xyz="0 0 1"/>
    <mimic joint="psm1_pitch_back_joint" multiplier="1"/>
    <limit effort="1000" lower="-0.93556" upper="0.94249" velocity="10"/>
  </joint>
  <link name="psm1_remote_center_link"/>
  <joint name="psm1_remote_center_joint" type="fixed">
    <parent link="psm1_base_link"/>
    <child link="psm1_remote_center_link"/>
    <origin rpy="0 0 0" xyz="0 0.4864 0"/>
  </joint>
  <joint name="psm2_rev_joint" type="revolute">
    <parent link="suj_psm2_L4"/>
    <child link="psm2_base_link"/>
    <origin rpy="0 3.14159 0" xyz="0 0.3479 -0.0495"/>
    <axis xyz="0 0 1"/>
    <limit effort="1000" lower="-3.14159" upper="3.14159" velocity="10"/>
  </joint>
  <link name="psm2_base_link">
    <inertial>
      <origin rpy="0 0 0" xyz="0 -0.17016 -0.085607"/>
      <mass value="2.0161"/>
      <inertia ixx="0" ixy="0" ixz="0" iyy="0" iyz="0" izz="0"/>
    </inertial>
    <visual>
      <origin rpy="0 0 0" xyz="0 0 0"/>
      <geometry>
        <mesh filename="package://dvrk_description/psm/meshes/base_link.STL"/>
      </geometry>
      <material name="">
        <color rgba="0.89804 0.91765 0.92941 1"/>
      </material>
    </visual>
    <collision>
      <origin rpy="0 0 0" xyz="0 0 0"/>
      <geometry>
        <mesh filename="package://dvrk_description/psm/meshes/base_link.STL"/>
      </geometry>
    </collision>
  </link>
  <link name="psm2_yaw_link">
    <inertial>
      <origin rpy="0 0 0" xyz="-0.038769 0 0.041596"/>
      <mass value="1.4705"/>
      <inertia ixx="0" ixy="0" ixz="0" iyy="0" iyz="0" izz="0"/>
    </inertial>
    <visual>
      <origin rpy="0 0 0" xyz="0 0 0"/>
      <geometry>
        <mesh filename="package://dvrk_description/psm/meshes/yaw_link.STL"/>
      </geometry>
      <material name="">
        <color rgba="0.89804 0.91765 0.92941 1"/>
      </material>
    </visual>
    <collision>
      <origin rpy="0 0 0" xyz="0 0 0"/>
      <geometry>
        <mesh filename="package://dvrk_description/psm/meshes/yaw_link.STL"/>
      </geometry>
    </collision>
  </link>
  <joint name="psm2_yaw_joint" type="revolute">
    <origin rpy="1.5708 -1.5708 0" xyz="0 0 0"/>
    <parent link="psm2_base_link"/>
    <child link="psm2_yaw_link"/>
    <axis xyz="0 0 1"/>
    <limit effort="1000" lower="-1.605" upper="1.5994" velocity="10"/>
  </joint>
  <link name="psm2_pitch_back_link">
    <inertial>
      <origin rpy="0 0 0" xyz="-0.011651 -0.036241 0"/>
      <mass value="0.98494"/>
      <inertia ixx="0" ixy="0" ixz="0" iyy="0" iyz="0" izz="0"/>
    </inertial>
    <visual>
      <origin rpy="0 0 0" xyz="0 0 0"/>
      <geometry>
        <mesh filename="package://dvrk_description/psm/meshes/pitch_back_link.STL"/>
      </geometry>
      <material name="">
        <color rgba="0.89804 0.91765 0.92941 1"/>
      </material>
    </visual>
    <collision>
      <origin rpy="0 0 0" xyz="0 0 0"/>
      <geometry>
        <mesh filename="package://dvrk_description/psm/meshes/pitch_back_link.STL"/>
      </geometry>
    </collision>
  </link>
  <joint name="psm2_pitch_back_joint" type="revolute">
    <origin rpy="-1.5708 -0.29073 0" xyz="0 0 0.0296"/>
    <parent link="psm2_yaw_link"/>
    <child link="psm2_pitch_back_link"/>
    <axis xyz="0 0 1"/>
    <limit effort="1000" lower="-0.93556" upper="0.94249" velocity="10"/>
  </joint>
  <link name="psm2_pitch_bottom_link">
    <inertial>
      <origin rpy="0 0 0" xyz="0.25683 -0.010348 0"/>
      <mass value="0.44569"/>
      <inertia ixx="0" ixy="0" ixz="0" iyy="0" iyz="0" izz="0"/>
    </inertial>
    <visual>
      <origin rpy="0 0 0" xyz="0 0 0"/>
      <geometry>
        <mesh filename="package://dvrk_description/psm/meshes/pitch_bottom_link.STL"/>
      </geometry>
      <material name="">
        <color rgba="0.89804 0.91765 0.92941 1"/>
      </material>
    </visual>
    <collision>
      <origin rpy="0 0 0" xyz="0 0 0"/>
      <geometry>
        <mesh filename="package://dvrk_description/psm/meshes/pitch_bottom_link.STL"/>
      </geometry>
    </collision>
  </link>
  <joint name="psm2_pitch_bottom_joint" type="revolute">
    <origin rpy="0 0 1.8615" xyz="0.15 0 0"/>
    <parent link="psm2_pitch_back_link"/>
    <child link="psm2_pitch_bottom_link"/>
    <axis xyz="0 0 1"/>
    <limit effort="1000" lower="-0.94249" upper="0.93556" velocity="10"/>
    <mimic joint="psm2_pitch_back_joint" multiplier="-1"/>
  </joint>
  <link name="psm2_pitch_end_link">
    <inertial>
      <origin rpy="0 0 0" xyz="-0.0019293 -0.13613 0"/>
      <mass value="2.091"/>
      <inertia ixx="0" ixy="0" ixz="0" iyy="0" iyz="0" izz="0"/>
    </inertial>
    <visual>
      <origin rpy="0 0 0" xyz="0 0 0"/>
      <geometry>
        <mesh filename="package://dvrk_description/psm/meshes/pitch_end_link.STL"/>
      </geometry>
      <material name="">
        <color rgba="0.89804 0.91765 0.92941 1"/>
      </material>
    </visual>
    <collision>
      <origin rpy="0 0 0" xyz="0 0 0"/>
      <geometry>
        <mesh filename="package://dvrk_description/psm/meshes/pitch_end_link.STL"/>
      </geometry>
    </collision>
  </link>
  <joint name="psm2_pitch_end_joint" type="revolute">
    <origin rpy="0 0 0" xyz="0.516 0 0"/>
    <parent link="psm2_pitch_bottom_link"/>
    <child link="psm2_pitch_end_link"/>
    <axis xyz="0 0 1"/>
    <limit effort="1000" lower="-0.93556" upper="0.94249" velocity="10"/>
    <mimic joint="psm2_pitch_back_joint" multiplier="1"/>
  </joint>
  <link name="psm2_main_insertion_link">
    <inertial>
      <origin rpy="0 0 0" xyz="0.0040563 -0.00010934 0.0098616"/>
      <mass value="0.22491"/>
      <inertia ixx="0" ixy="0" ixz="0" iyy="0" iyz="0" izz="0"/>
    </inertial>
    <visual>
      <origin rpy="0 0 1.5708" xyz="0 0 0"/>
      <geometry>
        <mesh filename="package://dvrk_description/psm/meshes/main_insertion_link.STL"/>
      </geometry>
      <material name="">
        <color rgba="1 0.55686 0.058824 0.4"/>
      </material>
    </visual>
    <collision>
      <origin rpy="0 0 0" xyz="0 0 0"/>
      <geometry>
        <mesh filename="package://dvrk_description/psm/meshes/main_insertion_link.STL"/>
      </geometry>
    </collision>
  </link>
  <joint name="psm2_main_insertion_joint" type="prismatic">
    <origin rpy="1.5708 1.5708 3.1416" xyz="0.043 -0.28809 0"/>
    <parent link="psm2_pitch_end_link"/>
    <child link="psm2_main_insertion_link"/>
    <axis xyz="0 0 1"/>
    <limit effort="1000" lower="0" upper="0.24" velocity="1"/>
  </joint>
  <link name="psm2_tool_roll_link">
    <inertial>
      <origin rpy="0 0 0" xyz="0 0 -0.0058234"/>
      <mass value="0.00033225"/>
      <inertia ixx="0" ixy="0" ixz="0" iyy="0" iyz="0" izz="0"/>
    </inertial>
    <visual>
      <origin rpy="0 0 0" xyz="0 0 0"/>
      <geometry>
        <mesh filename="package://dvrk_description/psm/meshes/tool_roll_link.STL"/>
      </geometry>
      <material name="">
        <color rgba="0.79608 0.82353 0.93725 1"/>
      </material>
    </visual>
    <collision>
      <origin rpy="0 0 0" xyz="0 0 0"/>
      <geometry>
        <mesh filename="package://dvrk_description/psm/meshes/tool_roll_link.STL"/>
      </geometry>
    </collision>
  </link>
  <joint name="psm2_tool_roll_joint" type="revolute">
    <origin rpy="0 0 -1.5708" xyz="0 0 0.4162"/>
    <parent link="psm2_main_insertion_link"/>
    <child link="psm2_tool_roll_link"/>
    <axis xyz="0 0 1"/>
    <limit effort="1000" lower="-3.14159" upper="3.14159" velocity="10"/>
  </joint>
  <link name="psm2_tool_pitch_link">
    <inertial>
      <origin rpy="0 0 0" xyz="0.0035763 0 0"/>
      <mass value="0.00025784"/>
      <inertia ixx="0" ixy="0" ixz="0" iyy="0" iyz="0" izz="0"/>
    </inertial>
    <visual>
      <origin rpy="0 0 0" xyz="0 0 0"/>
      <geometry>
        <mesh filename="package://dvrk_description/psm/meshes/tool_pitch_link.STL"/>
      </geometry>
      <material name="">
        <color rgba="0.79608 0.82353 0.93725 1"/>
      </material>
    </visual>
    <collision>
      <origin rpy="0 0 0" xyz="0 0 0"/>
      <geometry>
        <mesh filename="package://dvrk_description/psm/meshes/tool_pitch_link.STL"/>
      </geometry>
    </collision>
  </link>
  <joint name="psm2_tool_pitch_joint" type="revolute">
    <origin rpy="1.5708 -1.5708 3.1416" xyz="0 0 0"/>
    <parent link="psm2_tool_roll_link"/>
    <child link="psm2_tool_pitch_link"/>
    <axis xyz="0 0 1"/>
    <limit effort="1000" lower="-1.5708" upper="1.5708" velocity="10"/>
  </joint>
  <link name="psm2_tool_yaw_link">
    <inertial>
      <origin rpy="0 0 0" xyz="0 0 0"/>
      <mass value="0"/>
      <inertia ixx="0" ixy="0" ixz="0" iyy="0" iyz="0" izz="0"/>
    </inertial>
    <visual>
      <origin rpy="0 0 0" xyz="0 0 0"/>
      <geometry>
        <mesh filename="package://dvrk_description/psm/meshes/tool_yaw_link.STL"/>
      </geometry>
      <material name="">
        <color rgba="0.79608 0.82353 0.93725 1"/>
      </material>
    </visual>
    <collision>
      <origin rpy="0 0 0" xyz="0 0 0"/>
      <geometry>
        <mesh filename="package://dvrk_description/psm/meshes/tool_yaw_link.STL"/>
      </geometry>
    </collision>
  </link>
  <joint name="psm2_tool_yaw_joint" type="revolute">
    <origin rpy="1.5708 -1.5708 3.1416" xyz="0.0091 0 0"/>
    <parent link="psm2_tool_pitch_link"/>
    <child link="psm2_tool_yaw_link"/>
    <axis xyz="0 0 1"/>
    <limit effort="1000" lower="-1.5708" upper="1.5708" velocity="10"/>
  </joint>
  <link name="psm2_tool_gripper1_link">
    <inertial>
      <origin rpy="0 0 0" xyz="0.00019605 0.001435 -0.00088478"/>
      <mass value="0"/>
      <inertia ixx="0" ixy="0" ixz="0" iyy="0" iyz="0" izz="0"/>
    </inertial>
    <visual>
      <origin rpy="0 0 0" xyz="0 0 0"/>
      <geometry>
        <mesh filename="package://dvrk_description/psm/meshes/tool_gripper1_link.STL"/>
      </geometry>
      <material name="">
        <color rgba="0.79608 0.82353 0.93725 1"/>
      </material>
    </visual>
    <collision>
      <origin rpy="0 0 0" xyz="0 0 0"/>
      <geometry>
        <mesh filename="package://dvrk_description/psm/meshes/tool_gripper1_link.STL"/>
      </geometry>
    </collision>
  </link>
  <joint name="psm2_tool_gripper1_joint" type="revolute">
    <origin rpy="0 0 0" xyz="0 0 0"/>
    <parent link="psm2_tool_yaw_link"/>
    <child link="psm2_tool_gripper1_link"/>
    <axis xyz="0 0 1"/>
    <mimic joint="psm2_tool_gripper2_joint" multiplier="-1"/>
    <limit effort="0" lower="0" upper="1" velocity="0"/>
  </joint>
  <link name="psm2_tool_gripper2_link">
    <inertial>
      <origin rpy="0 0 0" xyz="-0.00019605 0.001435 0.00088478"/>
      <mass value="0"/>
      <inertia ixx="0" ixy="0" ixz="0" iyy="0" iyz="0" izz="0"/>
    </inertial>
    <visual>
      <origin rpy="0 0 0" xyz="0 0 0"/>
      <geometry>
        <mesh filename="package://dvrk_description/psm/meshes/tool_gripper2_link.STL"/>
      </geometry>
      <material name="">
        <color rgba="0.79608 0.82353 0.93725 1"/>
      </material>
    </visual>
    <collision>
      <origin rpy="0 0 0" xyz="0 0 0"/>
      <geometry>
        <mesh filename="package://dvrk_description/psm/meshes/tool_gripper2_link.STL"/>
      </geometry>
    </collision>
  </link>
  <joint name="psm2_tool_gripper2_joint" type="revolute">
    <origin rpy="0 0 0" xyz="0 0 0"/>
    <parent link="psm2_tool_yaw_link"/>
    <child link="psm2_tool_gripper2_link"/>
    <axis xyz="0 0 1"/>
    <limit effort="0" lower="0" upper="1" velocity="0"/>
  </joint>
  <link name="psm2_pitch_top_link">
    <inertial>
      <origin rpy="0 0 0" xyz="0.31246 -0.00056566 0"/>
      <mass value="0.17841"/>
      <inertia ixx="0" ixy="0" ixz="0" iyy="0" iyz="0" izz="0"/>
    </inertial>
    <visual>
      <origin rpy="0 0 0" xyz="0 0 0"/>
      <geometry>
        <mesh filename="package://dvrk_description/psm/meshes/pitch_top_link.STL"/>
      </geometry>
      <material name="">
        <color rgba="0.89804 0.91765 0.92941 1"/>
      </material>
    </visual>
    <collision>
      <origin rpy="0 0 0" xyz="0 0 0"/>
      <geometry>
        <mesh filename="package://dvrk_description/psm/meshes/pitch_top_link.STL"/>
      </geometry>
    </collision>
  </link>
  <joint name="psm2_pitch_top_joint" type="revolute">
    <origin rpy="0 0 1.8615" xyz="0.18366 0.014121 0"/>
    <parent link="psm2_pitch_back_link"/>
    <child link="psm2_pitch_top_link"/>
    <axis xyz="0 0 1"/>
    <limit effort="1000" lower="-0.94249" upper="0.93556" velocity="10"/>
    <mimic joint="psm2_pitch_back_joint" multiplier="-1"/>
  </joint>
  <link name="psm2_pitch_front_link">
    <inertial>
      <origin rpy="0 0 0" xyz="0.096269 0 0.047551"/>
      <mass value="0.074425"/>
      <inertia ixx="0" ixy="0" ixz="0" iyy="0" iyz="0" izz="0"/>
    </inertial>
    <visual>
      <origin rpy="0 0 0" xyz="0 0 0"/>
      <geometry>
        <mesh filename="package://dvrk_description/psm/meshes/pitch_front_link.STL"/>
      </geometry>
      <material name="">
        <color rgba="0.89804 0.91765 0.92941 1"/>
      </material>
    </visual>
    <collision>
      <origin rpy="0 0 0" xyz="0 0 0"/>
      <geometry>
        <mesh filename="package://dvrk_description/psm/meshes/pitch_front_link.STL"/>
      </geometry>
    </collision>
  </link>
  <joint name="psm2_pitch_front_joint" type="revolute">
    <origin rpy="-1.5708 -0.29073 0" xyz="0 0 -0.0664"/>
    <parent link="psm2_yaw_link"/>
    <child link="psm2_pitch_front_link"/>
    <axis xyz="0 0 1"/>
    <mimic joint="psm2_pitch_back_joint" multiplier="1"/>
    <limit effort="1000" lower="-0.93556" upper="0.94249" velocity="10"/>
  </joint>
  <link name="psm2_remote_center_link"/>
  <joint name="psm2_remote_center_joint" type="fixed">
    <parent link="psm2_base_link"/>
    <child link="psm2_remote_center_link"/>
    <origin rpy="0 0 0" xyz="0 0.4864 0"/>
  </joint>
  <joint name="psm3_rev_joint" type="revolute">
    <parent link="suj_psm3_L4"/>
    <child link="psm3_base_link"/>
    <origin rpy="0 3.14159 0" xyz="0 0.3479 -0.0495"/>
    <axis xyz="0 0 1"/>
    <limit effort="1000" lower="-3.14159" upper="3.14159" velocity="10"/>
  </joint>
  <link name="psm3_base_link">
    <inertial>
      <origin rpy="0 0 0" xyz="0 -0.17016 -0.085607"/>
      <mass value="2.0161"/>
      <inertia ixx="0" ixy="0" ixz="0" iyy="0" iyz="0" izz="0"/>
    </inertial>
    <visual>
      <origin rpy="0 0 0" xyz="0 0 0"/>
      <geometry>
        <mesh filename="package://dvrk_description/psm/meshes/base_link.STL"/>
      </geometry>
      <material name="">
        <color rgba="0.89804 0.91765 0.92941 1"/>
      </material>
    </visual>
    <collision>
      <origin rpy="0 0 0" xyz="0 0 0"/>
      <geometry>
        <mesh filename="package://dvrk_description/psm/meshes/base_link.STL"/>
      </geometry>
    </collision>
  </link>
  <link name="psm3_yaw_link">
    <inertial>
      <origin rpy="0 0 0" xyz="-0.038769 0 0.041596"/>
      <mass value="1.4705"/>
      <inertia ixx="0" ixy="0" ixz="0" iyy="0" iyz="0" izz="0"/>
    </inertial>
    <visual>
      <origin rpy="0 0 0" xyz="0 0 0"/>
      <geometry>
        <mesh filename="package://dvrk_description/psm/meshes/yaw_link.STL"/>
      </geometry>
      <material name="">
        <color rgba="0.89804 0.91765 0.92941 1"/>
      </material>
    </visual>
    <collision>
      <origin rpy="0 0 0" xyz="0 0 0"/>
      <geometry>
        <mesh filename="package://dvrk_description/psm/meshes/yaw_link.STL"/>
      </geometry>
    </collision>
  </link>
  <joint name="psm3_yaw_joint" type="revolute">
    <origin rpy="1.5708 -1.5708 0" xyz="0 0 0"/>
    <parent link="psm3_base_link"/>
    <child link="psm3_yaw_link"/>
    <axis xyz="0 0 1"/>
    <limit effort="1000" lower="-1.605" upper="1.5994" velocity="10"/>
  </joint>
  <link name="psm3_pitch_back_link">
    <inertial>
      <origin rpy="0 0 0" xyz="-0.011651 -0.036241 0"/>
      <mass value="0.98494"/>
      <inertia ixx="0" ixy="0" ixz="0" iyy="0" iyz="0" izz="0"/>
    </inertial>
    <visual>
      <origin rpy="0 0 0" xyz="0 0 0"/>
      <geometry>
        <mesh filename="package://dvrk_description/psm/meshes/pitch_back_link.STL"/>
      </geometry>
      <material name="">
        <color rgba="0.89804 0.91765 0.92941 1"/>
      </material>
    </visual>
    <collision>
      <origin rpy="0 0 0" xyz="0 0 0"/>
      <geometry>
        <mesh filename="package://dvrk_description/psm/meshes/pitch_back_link.STL"/>
      </geometry>
    </collision>
  </link>
  <joint name="psm3_pitch_back_joint" type="revolute">
    <origin rpy="-1.5708 -0.29073 0" xyz="0 0 0.0296"/>
    <parent link="psm3_yaw_link"/>
    <child link="psm3_pitch_back_link"/>
    <axis xyz="0 0 1"/>
    <limit effort="1000" lower="-0.93556" upper="0.94249" velocity="10"/>
  </joint>
  <link name="psm3_pitch_bottom_link">
    <inertial>
      <origin rpy="0 0 0" xyz="0.25683 -0.010348 0"/>
      <mass value="0.44569"/>
      <inertia ixx="0" ixy="0" ixz="0" iyy="0" iyz="0" izz="0"/>
    </inertial>
    <visual>
      <origin rpy="0 0 0" xyz="0 0 0"/>
      <geometry>
        <mesh filename="package://dvrk_description/psm/meshes/pitch_bottom_link.STL"/>
      </geometry>
      <material name="">
        <color rgba="0.89804 0.91765 0.92941 1"/>
      </material>
    </visual>
    <collision>
      <origin rpy="0 0 0" xyz="0 0 0"/>
      <geometry>
        <mesh filename="package://dvrk_description/psm/meshes/pitch_bottom_link.STL"/>
      </geometry>
    </collision>
  </link>
  <joint name="psm3_pitch_bottom_joint" type="revolute">
    <origin rpy="0 0 1.8615" xyz="0.15 0 0"/>
    <parent link="psm3_pitch_back_link"/>
    <child link="psm3_pitch_bottom_link"/>
    <axis xyz="0 0 1"/>
    <limit effort="1000" lower="-0.94249" upper="0.93556" velocity="10"/>
    <mimic joint="psm3_pitch_back_joint" multiplier="-1"/>
  </joint>
  <link name="psm3_pitch_end_link">
    <inertial>
      <origin rpy="0 0 0" xyz="-0.0019293 -0.13613 0"/>
      <mass value="2.091"/>
      <inertia ixx="0" ixy="0" ixz="0" iyy="0" iyz="0" izz="0"/>
    </inertial>
    <visual>
      <origin rpy="0 0 0" xyz="0 0 0"/>
      <geometry>
        <mesh filename="package://dvrk_description/psm/meshes/pitch_end_link.STL"/>
      </geometry>
      <material name="">
        <color rgba="0.89804 0.91765 0.92941 1"/>
      </material>
    </visual>
    <collision>
      <origin rpy="0 0 0" xyz="0 0 0"/>
      <geometry>
        <mesh filename="package://dvrk_description/psm/meshes/pitch_end_link.STL"/>
      </geometry>
    </collision>
  </link>
  <joint name="psm3_pitch_end_joint" type="revolute">
    <origin rpy="0 0 0" xyz="0.516 0 0"/>
    <parent link="psm3_pitch_bottom_link"/>
    <child link="psm3_pitch_end_link"/>
    <axis xyz="0 0 1"/>
    <limit effort="1000" lower="-0.93556" upper="0.94249" velocity="10"/>
    <mimic joint="psm3_pitch_back_joint" multiplier="1"/>
  </joint>
  <link name="psm3_main_insertion_link">
    <inertial>
      <origin rpy="0 0 0" xyz="0.0040563 -0.00010934 0.0098616"/>
      <mass value="0.22491"/>
      <inertia ixx="0" ixy="0" ixz="0" iyy="0" iyz="0" izz="0"/>
    </inertial>
    <visual>
      <origin rpy="0 0 1.5708" xyz="0 0 0"/>
      <geometry>
        <mesh filename="package://dvrk_description/psm/meshes/main_insertion_link.STL"/>
      </geometry>
      <material name="">
        <color rgba="1 0.55686 0.058824 0.4"/>
      </material>
    </visual>
    <collision>
      <origin rpy="0 0 0" xyz="0 0 0"/>
      <geometry>
        <mesh filename="package://dvrk_description/psm/meshes/main_insertion_link.STL"/>
      </geometry>
    </collision>
  </link>
  <joint name="psm3_main_insertion_joint" type="prismatic">
    <origin rpy="1.5708 1.5708 3.1416" xyz="0.043 -0.28809 0"/>
    <parent link="psm3_pitch_end_link"/>
    <child link="psm3_main_insertion_link"/>
    <axis xyz="0 0 1"/>
    <limit effort="1000" lower="0" upper="0.24" velocity="1"/>
  </joint>
  <link name="psm3_tool_roll_link">
    <inertial>
      <origin rpy="0 0 0" xyz="0 0 -0.0058234"/>
      <mass value="0.00033225"/>
      <inertia ixx="0" ixy="0" ixz="0" iyy="0" iyz="0" izz="0"/>
    </inertial>
    <visual>
      <origin rpy="0 0 0" xyz="0 0 0"/>
      <geometry>
        <mesh filename="package://dvrk_description/psm/meshes/tool_roll_link.STL"/>
      </geometry>
      <material name="">
        <color rgba="0.79608 0.82353 0.93725 1"/>
      </material>
    </visual>
    <collision>
      <origin rpy="0 0 0" xyz="0 0 0"/>
      <geometry>
        <mesh filename="package://dvrk_description/psm/meshes/tool_roll_link.STL"/>
      </geometry>
    </collision>
  </link>
  <joint name="psm3_tool_roll_joint" type="revolute">
    <origin rpy="0 0 -1.5708" xyz="0 0 0.4162"/>
    <parent link="psm3_main_insertion_link"/>
    <child link="psm3_tool_roll_link"/>
    <axis xyz="0 0 1"/>
    <limit effort="1000" lower="-3.14159" upper="3.14159" velocity="10"/>
  </joint>
  <link name="psm3_tool_pitch_link">
    <inertial>
      <origin rpy="0 0 0" xyz="0.0035763 0 0"/>
      <mass value="0.00025784"/>
      <inertia ixx="0" ixy="0" ixz="0" iyy="0" iyz="0" izz="0"/>
    </inertial>
    <visual>
      <origin rpy="0 0 0" xyz="0 0 0"/>
      <geometry>
        <mesh filename="package://dvrk_description/psm/meshes/tool_pitch_link.STL"/>
      </geometry>
      <material name="">
        <color rgba="0.79608 0.82353 0.93725 1"/>
      </material>
    </visual>
    <collision>
      <origin rpy="0 0 0" xyz="0 0 0"/>
      <geometry>
        <mesh filename="package://dvrk_description/psm/meshes/tool_pitch_link.STL"/>
      </geometry>
    </collision>
  </link>
  <joint name="psm3_tool_pitch_joint" type="revolute">
    <origin rpy="1.5708 -1.5708 3.1416" xyz="0 0 0"/>
    <parent link="psm3_tool_roll_link"/>
    <child link="psm3_tool_pitch_link"/>
    <axis xyz="0 0 1"/>
    <limit effort="1000" lower="-1.5708" upper="1.5708" velocity="10"/>
  </joint>
  <link name="psm3_tool_yaw_link">
    <inertial>
      <origin rpy="0 0 0" xyz="0 0 0"/>
      <mass value="0"/>
      <inertia ixx="0" ixy="0" ixz="0" iyy="0" iyz="0" izz="0"/>
    </inertial>
    <visual>
      <origin rpy="0 0 0" xyz="0 0 0"/>
      <geometry>
        <mesh filename="package://dvrk_description/psm/meshes/tool_yaw_link.STL"/>
      </geometry>
      <material name="">
        <color rgba="0.79608 0.82353 0.93725 1"/>
      </material>
    </visual>
    <collision>
      <origin rpy="0 0 0" xyz="0 0 0"/>
      <geometry>
        <mesh filename="package://dvrk_description/psm/meshes/tool_yaw_link.STL"/>
      </geometry>
    </collision>
  </link>
  <joint name="psm3_tool_yaw_joint" type="revolute">
    <origin rpy="1.5708 -1.5708 3.1416" xyz="0.0091 0 0"/>
    <parent link="psm3_tool_pitch_link"/>
    <child link="psm3_tool_yaw_link"/>
    <axis xyz="0 0 1"/>
    <limit effort="1000" lower="-1.5708" upper="1.5708" velocity="10"/>
  </joint>
  <link name="psm3_tool_gripper1_link">
    <inertial>
      <origin rpy="0 0 0" xyz="0.00019605 0.001435 -0.00088478"/>
      <mass value="0"/>
      <inertia ixx="0" ixy="0" ixz="0" iyy="0" iyz="0" izz="0"/>
    </inertial>
    <visual>
      <origin rpy="0 0 0" xyz="0 0 0"/>
      <geometry>
        <mesh filename="package://dvrk_description/psm/meshes/tool_gripper1_link.STL"/>
      </geometry>
      <material name="">
        <color rgba="0.79608 0.82353 0.93725 1"/>
      </material>
    </visual>
    <collision>
      <origin rpy="0 0 0" xyz="0 0 0"/>
      <geometry>
        <mesh filename="package://dvrk_description/psm/meshes/tool_gripper1_link.STL"/>
      </geometry>
    </collision>
  </link>
  <joint name="psm3_tool_gripper1_joint" type="revolute">
    <origin rpy="0 0 0" xyz="0 0 0"/>
    <parent link="psm3_tool_yaw_link"/>
    <child link="psm3_tool_gripper1_link"/>
    <axis xyz="0 0 1"/>
    <mimic joint="psm3_tool_gripper2_joint" multiplier="-1"/>
    <limit effort="0" lower="0" upper="1" velocity="0"/>
  </joint>
  <link name="psm3_tool_gripper2_link">
    <inertial>
      <origin rpy="0 0 0" xyz="-0.00019605 0.001435 0.00088478"/>
      <mass value="0"/>
      <inertia ixx="0" ixy="0" ixz="0" iyy="0" iyz="0" izz="0"/>
    </inertial>
    <visual>
      <origin rpy="0 0 0" xyz="0 0 0"/>
      <geometry>
        <mesh filename="package://dvrk_description/psm/meshes/tool_gripper2_link.STL"/>
      </geometry>
      <material name="">
        <color rgba="0.79608 0.82353 0.93725 1"/>
      </material>
    </visual>
    <collision>
      <origin rpy="0 0 0" xyz="0 0 0"/>
      <geometry>
        <mesh filename="package://dvrk_description/psm/meshes/tool_gripper2_link.STL"/>
      </geometry>
    </collision>
  </link>
  <joint name="psm3_tool_gripper2_joint" type="revolute">
    <origin rpy="0 0 0" xyz="0 0 0"/>
    <parent link="psm3_tool_yaw_link"/>
    <child link="psm3_tool_gripper2_link"/>
    <axis xyz="0 0 1"/>
    <limit effort="0" lower="0" upper="1" velocity="0"/>
  </joint>
  <link name="psm3_pitch_top_link">
    <inertial>
      <origin rpy="0 0 0" xyz="0.31246 -0.00056566 0"/>
      <mass value="0.17841"/>
      <inertia ixx="0" ixy="0" ixz="0" iyy="0" iyz="0" izz="0"/>
    </inertial>
    <visual>
      <origin rpy="0 0 0" xyz="0 0 0"/>
      <geometry>
        <mesh filename="package://dvrk_description/psm/meshes/pitch_top_link.STL"/>
      </geometry>
      <material name="">
        <color rgba="0.89804 0.91765 0.92941 1"/>
      </material>
    </visual>
    <collision>
      <origin rpy="0 0 0" xyz="0 0 0"/>
      <geometry>
        <mesh filename="package://dvrk_description/psm/meshes/pitch_top_link.STL"/>
      </geometry>
    </collision>
  </link>
  <joint name="psm3_pitch_top_joint" type="revolute">
    <origin rpy="0 0 1.8615" xyz="0.18366 0.014121 0"/>
    <parent link="psm3_pitch_back_link"/>
    <child link="psm3_pitch_top_link"/>
    <axis xyz="0 0 1"/>
    <limit effort="1000" lower="-0.94249" upper="0.93556" velocity="10"/>
    <mimic joint="psm3_pitch_back_joint" multiplier="-1"/>
  </joint>
  <link name="psm3_pitch_front_link">
    <inertial>
      <origin rpy="0 0 0" xyz="0.096269 0 0.047551"/>
      <mass value="0.074425"/>
      <inertia ixx="0" ixy="0" ixz="0" iyy="0" iyz="0" izz="0"/>
    </inertial>
    <visual>
      <origin rpy="0 0 0" xyz="0 0 0"/>
      <geometry>
        <mesh filename="package://dvrk_description/psm/meshes/pitch_front_link.STL"/>
      </geometry>
      <material name="">
        <color rgba="0.89804 0.91765 0.92941 1"/>
      </material>
    </visual>
    <collision>
      <origin rpy="0 0 0" xyz="0 0 0"/>
      <geometry>
        <mesh filename="package://dvrk_description/psm/meshes/pitch_front_link.STL"/>
      </geometry>
    </collision>
  </link>
  <joint name="psm3_pitch_front_joint" type="revolute">
    <origin rpy="-1.5708 -0.29073 0" xyz="0 0 -0.0664"/>
    <parent link="psm3_yaw_link"/>
    <child link="psm3_pitch_front_link"/>
    <axis xyz="0 0 1"/>
    <mimic joint="psm3_pitch_back_joint" multiplier="1"/>
    <limit effort="1000" lower="-0.93556" upper="0.94249" velocity="10"/>
  </joint>
  <link name="psm3_remote_center_link"/>
  <joint name="psm3_remote_center_joint" type="fixed">
    <parent link="psm3_base_link"/>
    <child link="psm3_remote_center_link"/>
    <origin rpy="0 0 0" xyz="0 0.4864 0"/>
  </joint>
</robot>

